2024-05-09 00:34:43,031 ERROR [/home/tosh/python/ClassBasedView/ClassBasedView/middleware.py:17] この名前は使用できません。
Traceback (most recent call last):
  File "/home/tosh/miniconda3/envs/djangoenv/lib/python3.10/site-packages/django/core/handlers/base.py", line 197, in _get_response
    response = wrapped_callback(request, *callback_args, **callback_kwargs)
  File "/home/tosh/miniconda3/envs/djangoenv/lib/python3.10/site-packages/django/views/generic/base.py", line 103, in view
    return self.dispatch(request, *args, **kwargs)
  File "/home/tosh/miniconda3/envs/djangoenv/lib/python3.10/site-packages/django/views/generic/base.py", line 142, in dispatch
    return handler(request, *args, **kwargs)
  File "/home/tosh/miniconda3/envs/djangoenv/lib/python3.10/site-packages/django/views/generic/base.py", line 216, in get
    context = self.get_context_data(**kwargs)
  File "/home/tosh/python/ClassBasedView/store/views.py", line 61, in get_context_data
    raise Http404("この名前は使用できません。")
django.http.response.Http404: この名前は使用できません。
